<?xml version="1.0" encoding="utf-8"?>
<!-- =================================================================================== -->
<!-- |    This document was autogenerated by xacro from /home/filipe/ros/rosiSim_catkin_ws/src/rosi_defy/urdf/rosi.urdf.xacro | -->
<!-- |    EDITING THIS FILE BY HAND IS NOT RECOMMENDED                                 | -->
<!-- =================================================================================== -->
<!-- ROSI URDF MODEL -->
<robot name="rosi" xmlns:xacro="http://www.ros.org/wiki/xacro">
  <!-- ============ Defining  links ===============-->
  <!-- Defining base link -->
  <link name="base_link">
    <origin rpy="0 0 0" xyz="0 0 0"/>
    <visual>
      <geometry>
        <mesh filename="package://rosi_defy/urdf/meshes/rosi_base.stl"/>
      </geometry>
    </visual>
  </link>
  <link name="arm_1">
    <visual>
      <geometry>
        <mesh filename="package://rosi_defy/urdf/meshes/arm.stl"/>
      </geometry>
      <origin rpy="0 0 0" xyz="0.1805 0 0"/>
    </visual>
  </link>
  <link name="arm_2">
    <visual>
      <geometry>
        <mesh filename="package://rosi_defy/urdf/meshes/arm.stl"/>
      </geometry>
      <origin rpy="0 0 3.14" xyz="-0.1805 0 0"/>
    </visual>
  </link>
  <link name="arm_3">
    <visual>
      <geometry>
        <mesh filename="package://rosi_defy/urdf/meshes/arm.stl"/>
      </geometry>
      <origin rpy="0 0 0" xyz="0.1805 0 0"/>
    </visual>
  </link>
  <link name="arm_4">
    <visual>
      <geometry>
        <mesh filename="package://rosi_defy/urdf/meshes/arm.stl"/>
      </geometry>
      <origin rpy="0 0 3.14" xyz="-0.1805 0 0"/>
    </visual>
  </link>
  <link name="wheel_1">
    <visual>
      <geometry>
        <mesh filename="package://rosi_defy/urdf/meshes/wheel.stl"/>
      </geometry>
      <origin rpy="0 0 0" xyz="0 0 0"/>
    </visual>
  </link>
  <link name="wheel_2">
    <visual>
      <geometry>
        <mesh filename="package://rosi_defy/urdf/meshes/wheel.stl"/>
      </geometry>
      <origin rpy="0 0 0" xyz="0 0 0"/>
    </visual>
  </link>
  <link name="wheel_3">
    <visual>
      <geometry>
        <mesh filename="package://rosi_defy/urdf/meshes/wheel.stl"/>
      </geometry>
      <origin rpy="0 0 0" xyz="0 0 0"/>
    </visual>
  </link>
  <link name="wheel_4">
    <visual>
      <geometry>
        <mesh filename="package://rosi_defy/urdf/meshes/wheel.stl"/>
      </geometry>
      <origin rpy="0 0 0" xyz="0 0 0"/>
    </visual>
  </link>
  <!-- Defining sensors links -->
  <link name="velodyne">
    <visual>
      <geometry>
        <mesh filename="package://rosi_defy/urdf/meshes/velodyne.stl"/>
      </geometry>
    </visual>
  </link>
  <link name="kinect">
    <visual>
      <geometry>
        <mesh filename="package://rosi_defy/urdf/meshes/kinect.stl"/>
      </geometry>
      <origin rpy="-1.57 0 1.57" xyz="-0.023 0 0"/>
    </visual>
  </link>
  <link name="ur5_link_2">
    <visual>
      <geometry>
        <mesh filename="package://rosi_defy/urdf/meshes/ur5_link_2.stl"/>
      </geometry>
      <origin rpy="0 0 1.57" xyz="0 0 0.070"/>
    </visual>
  </link>
  <link name="ur5_link_3">
    <visual>
      <geometry>
        <mesh filename="package://rosi_defy/urdf/meshes/ur5_link_3.stl"/>
      </geometry>
      <origin rpy="1.57 0 1.57" xyz="0.212 0 0.064"/>
    </visual>
  </link>
  <link name="ur5_link_4">
    <visual>
      <geometry>
        <mesh filename="package://rosi_defy/urdf/meshes/ur5_link_4.stl"/>
      </geometry>
      <origin rpy="1.57 0 1.57" xyz="0.187 0 -0.058"/>
    </visual>
  </link>
  <link name="ur5_link_5">
    <visual>
      <geometry>
        <mesh filename="package://rosi_defy/urdf/meshes/ur5_link_5.stl"/>
      </geometry>
      <origin rpy="1.57 0 1.57" xyz="0 0 0.032"/>
    </visual>
  </link>
  <link name="ur5_link_6">
    <visual>
      <geometry>
        <mesh filename="package://rosi_defy/urdf/meshes/ur5_link_6.stl"/>
      </geometry>
      <origin rpy="0 0 1.57" xyz="0 0 0.042"/>
    </visual>
  </link>
  <link name="ur5_link_7">
    <visual>
      <geometry>
        <mesh filename="package://rosi_defy/urdf/meshes/ur5_link_7.stl"/>
      </geometry>
      <origin rpy="1.57 0 0" xyz="0 0 0.077"/>
    </visual>
  </link>
  <!-- Defining UR5 tool link -->
  <link name="tool_pointer">
    <visual>
      <geometry>
        <mesh filename="package://rosi_defy/urdf/meshes/tool_pointer.stl"/>
      </geometry>
      <origin rpy="1.57 0 -1.57" xyz="0 0 0"/>
    </visual>
  </link>
  <!-- ============ Defining JOINTS ===============-->
  <joint name="joint_arm_1" type="continuous">
    <parent link="base_link"/>
    <child link="arm_1"/>
    <origin rpy="1.57 0 0" xyz="0.3152 -0.2210 -0.0993"/>
    <axis xyz="0 0 1"/>
  </joint>
  <joint name="joint_arm_2" type="continuous">
    <parent link="base_link"/>
    <child link="arm_2"/>
    <origin rpy="1.57 0 0" xyz="-0.3152 -0.2210 -0.0993"/>
    <axis xyz="0 0 1"/>
  </joint>
  <joint name="joint_arm_3" type="continuous">
    <parent link="base_link"/>
    <child link="arm_3"/>
    <origin rpy="-1.57 0 0" xyz="0.3152 0.2210 -0.0993"/>
    <axis xyz="0 0 1"/>
  </joint>
  <joint name="joint_arm_4" type="continuous">
    <parent link="base_link"/>
    <child link="arm_4"/>
    <origin rpy="-1.57 0 0" xyz="-0.3152 0.2210 -0.0993"/>
    <axis xyz="0 0 1"/>
  </joint>
  <joint name="joint_wheel_1" type="continuous">
    <parent link="base_link"/>
    <child link="wheel_1"/>
    <origin rpy="1.57 0 0" xyz="0.3152 -0.2880 -0.0993"/>
    <axis xyz="0 0 1"/>
  </joint>
  <joint name="joint_wheel_2" type="continuous">
    <parent link="base_link"/>
    <child link="wheel_2"/>
    <origin rpy="1.57 0 0" xyz="-0.3152 -0.2880 -0.0993"/>
    <axis xyz="0 0 1"/>
  </joint>
  <joint name="joint_wheel_3" type="continuous">
    <parent link="base_link"/>
    <child link="wheel_3"/>
    <origin rpy="-1.57 3.14 0" xyz="0.3152 0.2880 -0.0993"/>
    <axis xyz="0 0 1"/>
  </joint>
  <joint name="joint_wheel_4" type="continuous">
    <parent link="base_link"/>
    <child link="wheel_4"/>
    <origin rpy="-1.57 3.14 0" xyz="-0.3152 0.2880 -0.0993"/>
    <axis xyz="0 0 1"/>
  </joint>
  <!-- Defining ur5 joints -->
  <joint name="joint_ur5_j1" type="revolute">
    <parent link="base_link"/>
    <child link="ur5_link_2"/>
    <origin rpy="0 0 -1.57" xyz="-0.138 -0.067 0.184"/>
    <limit effort="50" lower="-6.28" upper="6.28" velocity="1.57"/>
    <axis xyz="0 0 1"/>
  </joint>
  <joint name="joint_ur5_j2" type="revolute">
    <parent link="ur5_link_2"/>
    <child link="ur5_link_3"/>
    <origin rpy="0 -1.57 0" xyz="-0.070 0 0.066"/>
    <limit effort="50" lower="-6.28" upper="6.28" velocity="1.57"/>
    <axis xyz="0 0 1"/>
  </joint>
  <joint name="joint_ur5_j3" type="revolute">
    <parent link="ur5_link_3"/>
    <child link="ur5_link_4"/>
    <origin rpy="0 0 0" xyz="0.425 0 0"/>
    <limit effort="50" lower="-6.28" upper="6.28" velocity="1.57"/>
    <axis xyz="0 0 1"/>
  </joint>
  <joint name="joint_ur5_j4" type="revolute">
    <parent link="ur5_link_4"/>
    <child link="ur5_link_5"/>
    <origin rpy="0 0 0" xyz="0.392 0 0"/>
    <limit effort="50" lower="-6.28" upper="6.28" velocity="1.57"/>
    <axis xyz="0 0 1"/>
  </joint>
  <joint name="joint_ur5_j5" type="revolute">
    <parent link="ur5_link_5"/>
    <child link="ur5_link_6"/>
    <origin rpy="0 1.57 0" xyz="0.045 0 0.039"/>
    <limit effort="50" lower="-6.28" upper="6.28" velocity="1.57"/>
    <axis xyz="0 0 1"/>
  </joint>
  <joint name="joint_ur5_j6" type="revolute">
    <parent link="ur5_link_6"/>
    <child link="ur5_link_7"/>
    <origin rpy="0 -1.57 0" xyz="0.014 0 0.049"/>
    <limit effort="50" lower="-6.28" upper="6.28" velocity="1.57"/>
    <axis xyz="0 0 1"/>
  </joint>
  <!-- Defining tool joint -->
  <joint name="joint_l7_tool" type="fixed">
    <parent link="ur5_link_7"/>
    <child link="tool_pointer"/>
    <origin rpy="0 0 3.14" xyz="-0.018 0.034 0.195 "/>
  </joint>
  <!-- Defining sensor joints -->
  <joint name="joint_velodyne" type="fixed">
    <parent link="base_link"/>
    <child link="velodyne"/>
    <origin rpy="0 0.26 0" xyz="0.242 0.002 0.1655"/>
  </joint>
  <joint name="joint_kinect" type="revolute">
    <parent link="base_link"/>
    <child link="kinect"/>
    <origin rpy="1.57 1.57 0" xyz="0.3 0 0.009"/>
    <limit effort="30" lower="-0.79" upper="0.79" velocity="0.79"/>
    <axis xyz="0 0 1"/>
  </joint>
</robot>

